(dp1
S'output'
p2
S"<type 'exceptions.KeyError'> 'nome'"
p3
sS'layer'
p4
S'/home/leonardo/Downloads/web2py/applications/KidsAppManager/controllers/default.py'
p5
sS'code'
p6
S'<code object <module> at 0x7f04fdad47b0, file "/home/leonardo/Downloads/web2py/applications/KidsAppManager/controllers/default.py", line 8>'
p7
sS'snapshot'
p8
(dp9
sS'traceback'
p10
S'Traceback (most recent call last):\n  File "/home/leonardo/Downloads/web2py/gluon/restricted.py", line 219, in restricted\n    exec(ccode, environment)\n  File "/home/leonardo/Downloads/web2py/applications/KidsAppManager/controllers/default.py", line 87, in <module>\n  File "/home/leonardo/Downloads/web2py/gluon/globals.py", line 419, in <lambda>\n    self._caller = lambda f: f()\n  File "/home/leonardo/Downloads/web2py/gluon/tools.py", line 3982, in f\n    return action(*a, **b)\n  File "/home/leonardo/Downloads/web2py/applications/KidsAppManager/controllers/default.py", line 16, in index\n    aluno_id= db(db.cadastro.id>0).select(\'cadastro.nome\').first()\n  File "/home/leonardo/Downloads/web2py/gluon/packages/dal/pydal/objects.py", line 2249, in select\n    fields = adapter.expand_all(fields, tablenames)\n  File "/home/leonardo/Downloads/web2py/gluon/packages/dal/pydal/adapters/base.py", line 170, in expand_all\n    append(self.db[tablename][fieldname])\n  File "/home/leonardo/Downloads/web2py/gluon/packages/dal/pydal/objects.py", line 548, in __getitem__\n    raise KeyError(key)\nKeyError: \'nome\'\n'
p11
s.