(dp1
S'output'
p2
S'<class \'gluon.contrib.pymysql.err.InternalError\'> (1136, u"Column count doesn\'t match value count at row 1")'
p3
sS'layer'
p4
S'/home/leonardo/Downloads/web2py/applications/KidsAppManager/controllers/default.py'
p5
sS'code'
p6
S'<code object <module> at 0x7f9270051830, file "/home/leonardo/Downloads/web2py/applications/KidsAppManager/controllers/default.py", line 10>'
p7
sS'snapshot'
p8
(dp9
sS'traceback'
p10
S'Traceback (most recent call last):\n  File "/home/leonardo/Downloads/web2py/gluon/restricted.py", line 219, in restricted\n    exec(ccode, environment)\n  File "/home/leonardo/Downloads/web2py/applications/KidsAppManager/controllers/default.py", line 173, in <module>\n  File "/home/leonardo/Downloads/web2py/gluon/globals.py", line 419, in <lambda>\n    self._caller = lambda f: f()\n  File "/home/leonardo/Downloads/web2py/applications/KidsAppManager/controllers/default.py", line 152, in busca_aluno\n    db.frequencia.insert(**dados)\n  File "/home/leonardo/Downloads/web2py/gluon/packages/dal/pydal/objects.py", line 753, in insert\n    ret = self._db._adapter.insert(self, row.op_values())\n  File "/home/leonardo/Downloads/web2py/gluon/packages/dal/pydal/adapters/base.py", line 486, in insert\n    raise e\nInternalError: (1136, u"Column count doesn\'t match value count at row 1")\n'
p11
s.