(dp1
S'output'
p2
S"<class 'sqlite3.OperationalError'> no such column: db.auth_user.first_name"
p3
sS'layer'
p4
S'/home/leonardo/Downloads/web2py/applications/KidsAppManager/controllers/default.py'
p5
sS'code'
p6
S'<code object <module> at 0x7f7b6008f530, file "/home/leonardo/Downloads/web2py/applications/KidsAppManager/controllers/default.py", line 8>'
p7
sS'snapshot'
p8
(dp9
sS'traceback'
p10
S'Traceback (most recent call last):\n  File "/home/leonardo/Downloads/web2py/gluon/restricted.py", line 219, in restricted\n    exec(ccode, environment)\n  File "/home/leonardo/Downloads/web2py/applications/KidsAppManager/controllers/default.py", line 63, in <module>\n  File "/home/leonardo/Downloads/web2py/gluon/globals.py", line 419, in <lambda>\n    self._caller = lambda f: f()\n  File "/home/leonardo/Downloads/web2py/gluon/tools.py", line 3982, in f\n    return action(*a, **b)\n  File "/home/leonardo/Downloads/web2py/applications/KidsAppManager/controllers/default.py", line 10, in index\n    logado = db(db.auth_user.first_name).select(\'db.auth_user.first_name\').first()\n  File "/home/leonardo/Downloads/web2py/gluon/packages/dal/pydal/objects.py", line 2250, in select\n    return adapter.select(self.query, fields, attributes)\n  File "/home/leonardo/Downloads/web2py/gluon/packages/dal/pydal/adapters/sqlite.py", line 82, in select\n    return super(SQLite, self).select(query, fields, attributes)\n  File "/home/leonardo/Downloads/web2py/gluon/packages/dal/pydal/adapters/base.py", line 762, in select\n    return self._select_aux(sql, fields, attributes, colnames)\n  File "/home/leonardo/Downloads/web2py/gluon/packages/dal/pydal/adapters/base.py", line 718, in _select_aux\n    rows = self._select_aux_execute(sql)\n  File "/home/leonardo/Downloads/web2py/gluon/packages/dal/pydal/adapters/base.py", line 712, in _select_aux_execute\n    self.execute(sql)\n  File "/home/leonardo/Downloads/web2py/gluon/packages/dal/pydal/adapters/__init__.py", line 67, in wrap\n    return f(*args, **kwargs)\n  File "/home/leonardo/Downloads/web2py/gluon/packages/dal/pydal/adapters/base.py", line 412, in execute\n    rv = self.cursor.execute(command, *args[1:], **kwargs)\nOperationalError: no such column: db.auth_user.first_name\n'
p11
s.